Workbook

Sheet RESUMEN GENERAL LG
C1: STOCK EQUIPOS LG - CONSOLIDADO | I1: 45944
A2: CODIGO | B2: MODELO | C2: DESCRIPCION | D2: SERIE | E2: CAPACIDAD | F2: STOCK | G2: SISTEMA | H2: UBICACIÓN | I2: INGRESO | J2: COSTO ACTUAL | K2: COSTO COMPASS | L2: VARLOR OFERTA
F3: 1
A4: SECAD0RA GIANT C MAX 10.2 KG
A5: I22441 | B5: GIANT C MAX - OPL | C5: SECADORA C GAS LG C/SIS OPL,MOD:GIANT-C MAX,CAP:10.2KG 220/60/1PH | D5: 303KWMK87579 | E5: 10.2 KG | F5: 1 | G5: CDG27MSCPS | H5: PLANTA | I5: 45047 | J5: 1180.452 | K5: =+(L5-J5)/2+J5 -> 1635.226 | L5: 2090
A6: I22443 | B6: GIANT C MAX - OPL | C6: SECADORA C GAS LG C/SIS OPL,MOD:GIANT-C MAX,CAP:10.2KG 220/60/1PH | D6: 303KWS887574 | E6: 10.2 KG | F6: 1 | G6: CDG27MSCPS | H6: PLANTA | I6: 45047 | J6: 1180.452 | K6: =+(L6-J6)/2+J6 -> 1635.226 | L6: 2090
A7: I22992 | B7: GIANT C MAX - OPL | C7: SECADORA C GAS LG C/SIS OPL,MOD:GIANT-C MAX,CAP:10.2KG 220/60/1PH | D7: 501KWLR2B920 | E7: 10.2 KG | F7: 1 | G7: CDG27MSCPS | H7: PLANTA | I7: 45748 | J7: 1180.452 | K7: =+(L7-J7)/2+J7 -> 1635.226 | L7: 2090
A8: I22993 | B8: GIANT C MAX - OPL | C8: SECADORA C GAS LG C/SIS OPL,MOD:GIANT-C MAX,CAP:10.2KG 220/60/1PH | D8: 501KWTA2B921 | E8: 10.2 KG | F8: 1 | G8: CDG27MSCPS | H8: PLANTA | I8: 45748 | J8: 1180.452 | K8: =+(L8-J8)/2+J8 -> 1635.226 | L8: 2090
A9: I22994 | B9: GIANT C MAX - OPL | C9: SECADORA C GAS LG C/SIS OPL,MOD:GIANT-C MAX,CAP:10.2KG 220/60/1PH | D9: 501KWDJ2B922 | E9: 10.2 KG | F9: 1 | G9: CDG27MSCPS | H9: PLANTA | I9: 45748 | J9: 1180.452 | K9: =+(L9-J9)/2+J9 -> 1635.226 | L9: 2090
A10: I22995 | B10: GIANT C MAX - OPL | C10: SECADORA C GAS LG C/SIS OPL,MOD:GIANT-C MAX,CAP:10.2KG 220/60/1PH | D10: 501KWMK2B923 | E10: 10.2 KG | F10: 1 | G10: CDG27MSCPS | H10: PLANTA | I10: 45748 | J10: 1180.452 | K10: =+(L10-J10)/2+J10 -> 1635.226 | L10: 2090
A11: I22996 | B11: GIANT C MAX - OPL | C11: SECADORA C GAS LG C/SIS OPL,MOD:GIANT-C MAX,CAP:10.2KG 220/60/1PH | D11: 501KWEL2B924 | E11: 10.2 KG | F11: 1 | G11: CDG27MSCPS | H11: PLANTA | I11: 45748 | J11: 1180.452 | K11: =+(L11-J11)/2+J11 -> 1635.226 | L11: 2090
A12: I22997 | B12: GIANT C MAX - OPL | C12: SECADORA C GAS LG C/SIS OPL,MOD:GIANT-C MAX,CAP:10.2KG 220/60/1PH | D12: 501KWKS2B925 | E12: 10.2 KG | F12: 1 | G12: CDG27MSCPS | H12: PLANTA | I12: 45748 | J12: 1180.452 | K12: =+(L12-J12)/2+J12 -> 1635.226 | L12: 2090
A13: I22998 | B13: GIANT C MAX - OPL | C13: SECADORA C GAS LG C/SIS OPL,MOD:GIANT-C MAX,CAP:10.2KG 220/60/1PH | D13: 501KWUC2B926 | E13: 10.2 KG | F13: 1 | G13: CDG27MSCPS | H13: PLANTA | I13: 45748 | J13: 1180.452 | K13: =+(L13-J13)/2+J13 -> 1635.226 | L13: 2090
A14: I22999 | B14: GIANT C MAX - OPL | C14: SECADORA C GAS LG C/SIS OPL,MOD:GIANT-C MAX,CAP:10.2KG 220/60/1PH | D14: 501KWNM2B927 | E14: 10.2 KG | F14: 1 | G14: CDG27MSCPS | H14: PLANTA | I14: 45748 | J14: 1180.452 | K14: =+(L14-J14)/2+J14 -> 1635.226 | L14: 2090
A15: I23000 | B15: GIANT C MAX - OPL | C15: SECADORA C GAS LG C/SIS OPL,MOD:GIANT-C MAX,CAP:10.2KG 220/60/1PH | D15: 501KWAT2B928 | E15: 10.2 KG | F15: 1 | G15: CDG27MSCPS | H15: PLANTA | I15: 45748 | J15: 1180.452 | K15: =+(L15-J15)/2+J15 -> 1635.226 | L15: 2090
A16: I23001 | B16: GIANT C MAX - OPL | C16: SECADORA C GAS LG C/SIS OPL,MOD:GIANT-C MAX,CAP:10.2KG 220/60/1PH | D16: 501KWWZ2B929 | E16: 10.2 KG | F16: 1 | G16: CDG27MSCPS | H16: PLANTA | I16: 45748 | J16: 1180.452 | K16: =+(L16-J16)/2+J16 -> 1635.226 | L16: 2090
... A21: I23006 | B21: GIANT C MAX - OPL | C21: SECADORA C GAS LG C/SIS OPL,MOD:GIANT-C MAX,CAP:10.2KG 220/60/1PH | D21: 501KWRE2B934 | E21: 10.2 KG | F21: 1 | G21: CDG27MSCPS | H21: PLANTA | I21: 45748 | J21: 1180.452 | K21: =+(L21-J21)/2+J21 -> 1635.226 | L21: 2090
F22: =SUM(F5:F21) -> 17
A23: SECAD0RA GIANT C MAX APILABLE 10.2 KG
A24: I22118 | B24: GIANT C MAX - APILABLE | C24: SECADORA C GAS LG C/SIS OPL,MOD:GIANT-C MAX APIL,CAP:10.2KG 220/60/1PH | D24: 207KWMK04275 | E24: 10.2 KG | F24: 1 | G24: CDG27MUCPS | H24: PLANTA | I24: 45047 | J24: 1180.452 | K24: =+(L24-J24)/2+J24 -> 1635.226 | L24: 2090
A25: I22450 | B25: GIANT C MAX - APILABLE | C25: SECADORA C GAS LG C/SIS OPL,MOD:GIANT-C MAX APIL,CAP:10.2KG 220/60/1PH | D25: 303KWDJ87698 | E25: 10.2 KG | F25: 1 | G25: CDG27MUCPS | H25: EXHIBICION | I25: 45047 | J25: 1180.452 | K25: =+(L25-J25)/2+J25 -> 1635.226 | L25: 2090
A26: I22452 | B26: GIANT C MAX - APILABLE | C26: SECADORA C GAS LG C/SIS OPL,MOD:GIANT-C MAX APIL,CAP:10.2KG 220/60/1PH | D26: 303KWFN87683 | E26: 10.2 KG | F26: 1 | G26: CDG27MUCPS | H26: PLANTA | I26: 45047 | J26: 1180.452 | K26: =+(L26-J26)/2+J26 -> 1635.226 | L26: 2090
A27: I22456 | B27: GIANT C MAX - APILABLE | C27: SECADORA C GAS LG C/SIS OPL,MOD:GIANT-C MAX APIL,CAP:10.2KG 220/60/1PH | D27: 303KWLR87696 | E27: 10.2 KG | F27: 1 | G27: CDG27MUCPS | H27: EXHIBICION | I27: 45047 | J27: 1180.452 | K27: =+(L27-J27)/2+J27 -> 1635.226 | L27: 2090
A28: I22462 | B28: GIANT C MAX - APILABLE | C28: SECADORA C GAS LG C/SIS OPL,MOD:GIANT-C MAX APIL,CAP:10.2KG 220/60/1PH | D28: 303KWSB87694 | E28: 10.2 KG | F28: 1 | G28: CDG27MUCPS | H28: PLANTA | I28: 45047 | J28: 1180.452 | K28: =+(L28-J28)/2+J28 -> 1635.226 | L28: 2090
A29: I22467 | B29: GIANT C MAX - APILABLE | C29: SECADORA C GAS LG C/SIS OPL,MOD:GIANT-C MAX APIL,CAP:10.2KG 220/60/1PH | D29: 303KWXD87682 | E29: 10.2 KG | F29: 1 | G29: CDG27MUCPS | H29: PLANTA | I29: 45047 | J29: 1180.452 | K29: =+(L29-J29)/2+J29 -> 1635.226 | L29: 2090
A30: I22470 | B30: GIANT C MAX - APILABLE | C30: SECADORA C GAS LG C/SIS OPL,MOD:GIANT-C MAX APIL,CAP:10.2KG 220/60/1PH | D30: 303KWHX87689 | E30: 10.2 KG | F30: 1 | G30: CDG27MUCPS | H30: PLANTA | I30: 45047 | J30: 1180.452 | K30: =+(L30-J30)/2+J30 -> 1635.226 | L30: 2090
A31: I22531 | B31: GIANT C MAX - APILABLE | C31: SECADORA C GAS LG C/SIS OPL,MOD:GIANT-C MAX APIL,CAP:10.2KG 220/60/1PH | D31: 304KWGG0V223 | E31: 10.2 KG | F31: 1 | G31: CDG27MUCPS | H31: PLANTA | I31: 45078 | J31: 1180.452 | K31: =+(L31-J31)/2+J31 -> 1635.226 | L31: 2090
A32: I22532 | B32: GIANT C MAX - APILABLE | C32: SECADORA C GAS LG C/SIS OPL,MOD:GIANT-C MAX APIL,CAP:10.2KG 220/60/1PH | D32: 304KWHX0V217 | E32: 10.2 KG | F32: 1 | G32: CDG27MUCPS | H32: PLANTA | I32: 45078 | J32: 1180.452 | K32: =+(L32-J32)/2+J32 -> 1635.226 | L32: 2090
A33: I22533 | B33: GIANT C MAX - APILABLE | C33: SECADORA C GAS LG C/SIS OPL,MOD:GIANT-C MAX APIL,CAP:10.2KG 220/60/1PH | D33: 304KWLR0V200 | E33: 10.2 KG | F33: 1 | G33: CDG27MUCPS | H33: PLANTA | I33: 45078 | J33: 1180.452 | K33: =+(L33-J33)/2+J33 -> 1635.226 | L33: 2090
A34: I22534 | B34: GIANT C MAX - APILABLE | C34: SECADORA C GAS LG C/SIS OPL,MOD:GIANT-C MAX APIL,CAP:10.2KG 220/60/1PH | D34: 304KWLR0V224 | E34: 10.2 KG | F34: 1 | G34: CDG27MUCPS | H34: PLANTA | I34: 45078 | J34: 1180.452 | K34: =+(L34-J34)/2+J34 -> 1635.226 | L34: 2090
A35: I22535 | B35: GIANT C MAX - APILABLE | C35: SECADORA C GAS LG C/SIS OPL,MOD:GIANT-C MAX APIL,CAP:10.2KG 220/60/1PH | D35: 304KWMK0V203 | E35: 10.2 KG | F35: 1 | G35: CDG27MUCPS | H35: PLANTA | I35: 45078 | J35: 1180.452 | K35: =+(L35-J35)/2+J35 -> 1635.226 | L35: 2090
... A61: I22620 | B61: GIANT C MAX - APILABLE | C61: SECADORA C GAS LG C/SIS OPL,MOD:GIANT-C MAX APIL,CAP:10.2KG 220/60/1PH | D61: 304KWZH0V221 | E61: 10.2 KG | F61: 1 | G61: CDG27MUCPS | H61: PLANTA | I61: 45261 | J61: 1180.452 | K61: =+(L61-J61)/2+J61 -> 1635.226 | L61: 2090
F62: =SUM(F24:F61) -> 38
A63: SECADORA TITAN LIGHT 15 KG
A64: I22624 | B64: TITAN LIGHT - OPL | C64: SECADORA C. GAS LG C/S OPL, MOD. TITAN LIGTH CAP.15KG,220V/60HZ/1PH | D64: 302KWGG7Z471 | E64: 15 KG | F64: 1 | G64: CDT29MSCPS | H64: PLANTA | I64: 45261 | J64: 1461 | K64: =+(L64-J64)/2+J64 -> 2225.5 | L64: 2990
A65: I22800 | B65: TITAN LIGHT - OPL | C65: SECADORA C. GAS LG C/S OPL, MOD. TITAN LIGTH CAP. 15KG, 220V/60HZ/1PH | D65: 405KWATPG288 | E65: 15 KG | F65: 1 | G65: CDT29MSCPS | H65: PLANTA | I65: 45474 | J65: 1461 | K65: =+(L65-J65)/2+J65 -> 2225.5 | L65: 2990
A66: I22801 | B66: TITAN LIGHT - OPL | C66: SECADORA C. GAS LG C/S OPL, MOD. TITAN LIGTH CAP. 15KG, 220V/60HZ/1PH | D66: 405KWBYPG293 | E66: 15 KG | F66: 1 | G66: CDT29MSCPS | H66: PLANTA | I66: 45474 | J66: 1461 | K66: =+(L66-J66)/2+J66 -> 2225.5 | L66: 2990
A67: I22806 | B67: TITAN LIGHT - OPL | C67: SECADORA C. GAS LG C/S OPL, MOD. TITAN LIGTH CAP. 15KG, 220V/60HZ/1PH | D67: 405KWREPG294 | E67: 15 KG | F67: 1 | G67: CDT29MSCPS | H67: PLANTA | I67: 45474 | J67: 1461 | K67: =+(L67-J67)/2+J67 -> 2225.5 | L67: 2990
A68: I22808 | B68: TITAN LIGHT - OPL | C68: SECADORA C. GAS LG C/S OPL, MOD. TITAN LIGTH CAP. 15KG, 220V/60HZ/1PH | D68: 405KWWZPG289 | E68: 15 KG | F68: 1 | G68: CDT29MSCPS | H68: PLANTA | I68: 45474 | J68: 1461 | K68: =+(L68-J68)/2+J68 -> 2225.5 | L68: 2990
A69: I22842 | B69: TITAN LIGHT - OPL | C69: SECADORA C. GAS LG C/S OPL, MOD. TITAN LIGTH CAP. 15KG, 220V/60HZ/1PH | D69: 408KWJU30060 | E69: 15 KG | F69: 1 | G69: CDT29MSCPS | H69: PLANTA | I69: 45566 | J69: 1461 | K69: =+(L69-J69)/2+J69 -> 2225.5 | L69: 2990
...

Sheet RESUMEN LG 
G1: ='RESUMEN GENERAL LG'!I1 -> 45944
B2: STOCK DE EQUIPOS LG - CONSOLIDADO
B4: SECADORAS
B6: ITEM | C6: STOCK | D6: POR INGRESAR | E6: MARCA | F6: MODELO | G6: CAPACIDAD | H6: AÑO
B7: 2 | C7: ='RESUMEN GENERAL LG'!F3 -> 1 | D7: 0 | E7: LG | F7: TITAN C | G7: 15 KG | H7: 45047
B8: 4 | C8: ='RESUMEN GENERAL LG'!F22 -> 17 | D8: 0 | E8: LG | F8: GIANT C MAX | G8: 10.2 KG | H8: 45047
B9: 5 | C9: ='RESUMEN GENERAL LG'!F62 -> 38 | D9: 0 | E9: LG | F9: GIANT C MAX APILABLE | G9: 10.2 KG | H9: 45047
B10: 6 | C10: ='RESUMEN GENERAL LG'!F72 -> 8 | D10: 0 | E10: LG | F10: TITAN LIGHT | G10: 15 KG | H10: 45261
B11: 7 | C11: ='RESUMEN GENERAL LG'!F101 -> 27 | D11: 0 | E11: LG | F11: TITAN LIGHT APILABLE | G11: 15 KG | H11: 45566
C12: =SUM(C7:C11) -> 91 | D12: =SUM(D7:D11) -> 0
B13: LAVADORAS
B14: ITEM | C14: STOCK | D14: POR INGRESAR | E14: MARCA | F14: MODELO | G14: CAPACIDAD | H14: AÑO
B15: 1 | C15: ='RESUMEN GENERAL LG'!F126 -> 23 | D15: 0 | E15: LG | F15: GIANT C MAX | G15: 13 KG | H15: 45444
B16: 2 | C16: ='RESUMEN GENERAL LG'!F164 -> 36 | D16: 0 | E16: LG | F16: GIANT C MAX APILABLE | G16: 13 KG | H16: 45566
B17: 3 | C17: ='RESUMEN GENERAL LG'!F207 -> 41 | D17: 0 | E17: LG | F17: TITAN MAX | G17: 17 KG | H17: 45566
B18: 4 | C18: ='RESUMEN GENERAL LG'!F237 -> 28 | D18: 0 | E18: LG | F18: TITAN MAX APILABLE | G18: 17 KG | H18: 45566
C19: =SUM(C15:C18) -> 128 | D19: =SUM(D15:D18) -> 0
